<?xml version="1.0"?>
<robot name="single_prop_drone">

  <link name="base_link">
    <visual>
      <origin xyz="0 0 0" rpy="0 0 0.81"/>
      <geometry>
        <box size="0.2 0.2 0.05"/>
      </geometry>
      <material name="black">
        <color rgba="0 0 0 1"/>
      </material>
    </visual>
  </link>
  <joint name="joint_arm1" type="fixed">
    <parent link="base_link"/>
    <child link="arm1"/>
    <origin xyz="0.20 0 0" rpy="0 0 0"/>
   </joint>

   <link name="arm1">
    <visual>
      <origin xyz="0 0 0" rpy="1.57 1.57 0"/>
      <geometry>
        <cylinder radius="0.03" length="0.15"/>
      </geometry>
      <material name="gray">
        <color rgba="0.6 0.6 0.6 1"/>
      </material>
    </visual>
  </link>
  <joint name="joint_arm2" type="fixed">
    <parent link="base_link"/>
    <child link="arm2"/>
    <origin xyz="-0.20 0 0" rpy="0 0 0"/>
   </joint>

   <link name="arm2">
    <visual>
      <origin xyz="0 0 0" rpy="1.57 1.57 0"/>
      <geometry>
        <cylinder radius="0.03" length="0.15"/>
      </geometry>
      <material name="gray">
        <color rgba="0.6 0.6 0.6 1"/>
      </material>
    </visual>
  </link>

 <joint name="joint_arm3" type="fixed">
    <parent link="base_link"/>
    <child link="arm3"/>
    <origin xyz="0 -0.20 0" rpy="0 0 0"/>
   </joint>

   <link name="arm3">
    <visual>
      <origin xyz="0 0 0" rpy="1.57 0 0"/>
      <geometry>
        <cylinder radius="0.03" length="0.15"/>
      </geometry>
      <material name="gray">
        <color rgba="0.6 0.6 0.6 1"/>
      </material>
    </visual>
  </link>

 <joint name="joint_arm4" type="fixed">
    <parent link="base_link"/>
    <child link="arm4"/>
    <origin xyz="0 0.20 0" rpy="0 0 0"/>
   </joint>

   <link name="arm4">
    <visual>
      <origin xyz="0 0 0" rpy="1.57 0 0"/>
      <geometry>
        <cylinder radius="0.03" length="0.15"/>
      </geometry>
      <material name="gray">
        <color rgba="0.6 0.6 0.6 1"/>
      </material>
    </visual>
  </link>

<joint name="joint_motor1" type="fixed">
    <parent link="arm1"/>
    <child link="motor1"/>
    <origin xyz="0.095 0 0" rpy="0 0 0"/>
   </joint>

   <link name="motor1">
    <visual>
      <origin xyz="0 0 0" rpy="0 0 0"/>
      <geometry>
        <cylinder radius="0.03" length="0.15"/>
      </geometry>
      <material name="gray">
        <color rgba="0.6 0.6 0.6 1"/>
      </material>
    </visual>
  </link>
  <joint name="joint_motor2" type="fixed">
    <parent link="arm2"/>
    <child link="motor2"/>
    <origin xyz="-0.095 0 0" rpy="0 0 0"/>
   </joint>

   <link name="motor2">
    <visual>
      <origin xyz="0 0 0" rpy="0 0 0"/>
      <geometry>
        <cylinder radius="0.03" length="0.15"/>
      </geometry>
      <material name="gray">
        <color rgba="0.6 0.6 0.6 1"/>
      </material>
    </visual>
  </link>
  <joint name="joint_motor3" type="fixed">
    <parent link="arm3"/>
    <child link="motor3"/>
    <origin xyz="0 -0.095 0" rpy="0 0 0"/>
   </joint>

   <link name="motor3">
    <visual>
      <origin xyz="0 0 0" rpy="0 0 0"/>
      <geometry>
        <cylinder radius="0.03" length="0.15"/>
      </geometry>
      <material name="gray">
        <color rgba="0.6 0.6 0.6 1"/>
      </material>
    </visual>
  </link>
  <joint name="joint_motor4" type="fixed">
    <parent link="arm4"/>
    <child link="motor4"/>
    <origin xyz="0 0.095 0" rpy="0 0 0"/>
   </joint>

   <link name="motor4">
    <visual>
      <origin xyz="0 0 0" rpy="0 0 0"/>
      <geometry>
        <cylinder radius="0.03" length="0.15"/>
      </geometry>
      <material name="gray">
        <color rgba="0.6 0.6 0.6 1"/>
      </material>
    </visual>
  </link>

 <link name="prop1">
    <visual>
      <origin xyz="0 0 0.08" rpy="1.57 0 0"/>
      <geometry>
        <cylinder radius="0.008" length="0.3"/>
      </geometry>
      <material name="red">
        <color rgba="1 0 0 1"/>
      </material>
    </visual>
  </link>

  <joint name="joint_prop1" type="continuous">
    <parent link="motor1"/>
    <child link="prop1"/>
    <origin xyz="0.00" rpy="0 0 0"/>
    <axis xyz="0 0 1"/>
  </joint>

  <link name="prop2">
    <visual>
      <origin xyz="0 0 0.08" rpy="1.57 0 0"/>
      <geometry>
        <cylinder radius="0.008" length="0.3"/>
      </geometry>
      <material name="red">
        <color rgba="1 0 0 1"/>
      </material>
    </visual>
  </link>

  <joint name="joint_prop1" type="continuous">
    <parent link="motor2"/>
    <child link="prop2"/>
    <origin xyz="-00 0" rpy="0 0 0"/>
    <axis xyz="0 0 1"/>
  </joint>

  <link name="prop3">
    <visual>
      <origin xyz="0 0 0.08" rpy="1.57 0 0"/>
      <geometry>
        <cylinder radius="0.008" length="0.3"/>
      </geometry>
      <material name="red">
        <color rgba="1 0 0 1"/>
      </material>
    </visual>
  </link>

  <joint name="joint_prop3" type="continuous">
    <parent link="motor3"/>
    <child link="prop3"/>
    <origin xyz="0 0 0" rpy="0 0 0"/>
    <axis xyz="0 0 1"/>
  </joint>

  <link name="prop4">
    <visual>
      <origin xyz="0 0 0.08" rpy="1.57 0 0"/>
      <geometry>
        <cylinder radius="0.008" length="0.3"/>
      </geometry>
      <material name="red">
        <color rgba="1 0 0 1"/>
      </material>
    </visual>
  </link>

  <joint name="joint_prop4" type="continuous">
    <parent link="motor4"/>
    <child link="prop4"/>
    <origin xyz="0 0 0" rpy="0 0 0"/>
    <axis xyz="0 0 1"/>
  </joint>

</robot>